Workbook

Sheet Anleitung
A1: AetherRide — MVP-Backlog
A2: Abgeleitet aus der Produkt-, Architektur- und Design-Spezifikation v1.0 vom 06.08.2026
A4: Aufbau der Mappe
A5: Backlog | B5: Alle Stories mit Akzeptanzkriterien, Priorität, Phase, Abhängigkeit und Schätzung.
A6: Epics | B6: Auswertung je Epic. Alle Zahlen sind Formeln auf das Blatt Backlog — nicht überschreiben.
A7: Gates | B7: Sechs externe Entscheidungspunkte. Stories mit Gate-Eintrag starten erst nach positivem Gate.
A8: Risiken | B8: Risikoregister aus Kapitel 10 der Spezifikation.
A10: Was Sie bearbeiten
A11: Spalte K (SP) | B11: Story Points. Vorbelegt als Erstschätzung des Autors — im Planning ersetzen.
A12: Spalte M (Status) | B12: Auswahlliste: Offen, In Arbeit, Review, Fertig, Zurückgestellt.
A13: Epics!B3 (Velocity) | B13: Gelb hinterlegt. Story Points je Sprint. Vorgabe 90 ist aus dem Plan zurückgerechnet, nicht gemessen — sobald der echte Teamwert vorliegt, ersetzen. Weicht er ab, verschiebt sich der Launchtermin entsprechend.
A15: Alles Übrige ist abgeleitet
A16: Spalte H (Spec-Referenz) | B16: Verweis in die Spezifikation. Bei Änderung einer Story dort gegenprüfen.
A17: Spalte I (Abhängig von) | B17: Epic-Kürzel. Eine Story sollte nicht vor ihrer Abhängigkeit eingeplant werden.
A18: Spalte J (Gate) | B18: Leer bedeutet: jederzeit startbar.
A20: Beispielzeile (so ist eine Story gemeint)
A21: ST-030 | B21: Epic E04 · „Regel-Engine mit vier Urteilen“ · P0 · MVP v1.0 · Spec F-GAR-003 · 13 SP · Rolle Backend · Status Offen
A23: Wichtig
A24: Gate G-2 | B24: Sechs Stories der Fahrwerksanalyse sind an die Feldvalidierung gebunden. Scheitert sie, entfallen diese Stories ersatzlos — sie werden nicht abgeschwächt ausgeliefert.
A25: Katalogdaten | B25: Die Stories des Epics E16 sind der kritische Pfad, nicht die Softwareentwicklung. Sie müssen ab Monat 1 laufen.
A26: Schätzungen | B26: SP sind eine Erstschätzung ohne Teamkalibrierung. Die Sprint-Hochrechnung auf dem Blatt Epics ist deshalb eine Größenordnung, keine Terminzusage.

Sheet Backlog
A1: ID | B1: Epic | C1: Titel | D1: User Story | E1: Akzeptanzkriterien | F1: Prio | G1: Phase | H1: Spec-Ref | I1: Abhängig von | J1: Gate | K1: SP | L1: Rolle | M1: Status
A2: ST-001 | B2: E01 | C2: Mobile-Stack final bestätigen | D2: Als Engineering-Leitung will ich die Entscheidung Flutter + native Module gegen die reale Teamaufstellung prüfen, damit die Architektur zum Team passt. | E2: Entscheidungsmatrix mit tatsächlichen Teamprofilen neu bewertet; Ergebnis dokumentiert und freigegeben; bei Umkehr ist Kap. 5.1 aktualisiert. | F2: P0 | G2: MVP v1.0 | H2: 5.1 | J2: G-0 | K2: 3 | L2: Eng-Lead | M2: Offen
A3: ST-002 | B3: E01 | C3: Projektgerüst Flutter + CI | D3: Als Entwickler will ich ein lauffähiges Projektgerüst mit CI, damit ab Sprint 1 auf grüner Pipeline gearbeitet wird. | E3: Build für iOS und Android in CI; Lint, Format, Unit-Tests als Gate; Signierung eingerichtet; Build < 12 min. | F3: P0 | G3: MVP v1.0 | H3: 5.2 | K3: 5 | L3: Mobile | M3: Offen
A4: ST-003 | B4: E01 | C4: Schichtung und Repository-Muster | D4: Als Entwickler will ich die Schichten Präsentation/Zustand/Domäne/Repository festlegen, damit kein Lesepfad am Netz hängt. | E4: Referenzimplementierung für eine Entität vorhanden; Architekturtest schlägt fehl, wenn die UI direkt auf Netzwerkcode zugreift. | F4: P0 | G4: MVP v1.0 | H4: 5.2 | K4: 5 | L4: Mobile | M4: Offen
A5: ST-004 | B5: E01 | C5: dsp_core in Rust aufsetzen | D5: Als ML-Ingenieur will ich die Signalverarbeitung als plattformunabhängige Rust-Bibliothek, damit sie einmal geschrieben und auf dem Desktop getestet werden kann. | E5: Bibliothek baut für iOS, Android und Desktop; FFI-Anbindung an Dart; Referenzdatensatz läuft auf allen drei Zielen mit identischem Ergebnis. | F5: P0 | G5: MVP v1.0 | H5: 5.1 | K5: 8 | L5: ML | M5: Offen
A6: ST-005 | B6: E01 | C6: Blockweise Sensorübergabe über FFI | D6: Als Entwickler will ich Sensordaten in 1-Sekunden-Blöcken über gemeinsamen Speicher übergeben, damit die Method-Channel-Last entfällt. | E6: 200 Hz über 2 h ohne Frame-Drop; keine Einzelsample-Übergabe im Code; Messung dokumentiert. | F6: P0 | G6: MVP v1.0 | H6: 5.1 / F-SEN-001 | K6: 8 | L6: Mobile | M6: Offen
A7: ST-006 | B7: E01 | C7: Backend-Grundgerüst und Deployment | D7: Als Backend-Entwickler will ich die vier MVP-Deploymenteinheiten mit Postgres, Redis und Objektspeicher aufsetzen. | E7: Infrastruktur als Code; EU-Region; Health-Checks; automatisches Deployment aus dem Hauptzweig. | F7: P0 | G7: MVP v1.0 | H7: 5.3 | K7: 8 | L7: Backend | M7: Offen
A8: ST-007 | B8: E01 | C8: Schema-Trennung je Bounded Context | D8: Als Architekt will ich getrennte Datenbankschemata ohne kontextübergreifende Fremdschlüssel, damit ein späteres Herauslösen ein Deployment-Schritt bleibt. | E8: Migrationsprüfung schlägt bei kontextübergreifendem Fremdschlüssel fehl. | F8: P0 | G8: MVP v1.0 | H8: 5.3 | K8: 3 | L8: Backend | M8: Offen
A9: ST-008 | B9: E01 | C9: Observability | D9: Als Betreiber will ich Traces, Metriken und Absturzberichte, damit die NFR messbar sind. | E9: OpenTelemetry im Backend; Sentry in der App; Dashboards für NFR-01 bis NFR-11. | F9: P0 | G9: MVP v1.0 | H9: 5.7 | K9: 5 | L9: DevOps | M9: Offen
A10: ST-009 | B10: E01 | C10: OpenAPI-Vertrag und Client-Generierung | D10: Als Entwickler will ich einen versionierten API-Vertrag, aus dem der Client generiert wird. | E10: OpenAPI 3.1 im Repository; Client generiert; Vertragsbruch bricht die CI. | F10: P0 | G10: MVP v1.0 | H10: 5.3 | K10: 5 | L10: Backend | M10: Offen
A11: ST-010 | B11: E02 | C11: Nutzung ohne Konto | D11: Als neuer Nutzer will ich Garage und Tracking ohne Registrierung nutzen, damit ich die App sofort ausprobieren kann. | E11: Voller lokaler Funktionsumfang ohne Konto; Registrierung wird erst nach dem ersten Ride angeboten, mit Begründung. | F11: P0 | G11: MVP v1.0 | H11: F-ACC-002 | K11: 5 | L11: Mobile | M11: Offen
A12: ST-011 | B12: E02 | C12: Registrierung und Anmeldung | D12: Als Nutzer will ich mich per E-Mail, Apple oder Google anmelden, damit meine Daten geräteübergreifend erhalten bleiben. | E12: Drei Verfahren funktionsfähig; Token-Erneuerung; Abmelden löscht lokale Sitzung, nicht die lokalen Daten. | F12: P0 | G12: MVP v1.0 | H12: F-ACC-001 | I12: E01 | K12: 8 | L12: Backend | M12: Offen
A13: ST-012 | B13: E02 | C13: Sync-Engine mit Operations-Log | D13: Als Nutzer will ich offline arbeiten und später synchronisieren, ohne Daten zu verlieren. | E13: UUIDv7 clientseitig; geordnetes Operations-Log übersteht App-Neustart; Server idempotent gegenüber operation_id; Delta-Sync per Cursor. | F13: P0 | G13: MVP v1.0 | H13: 5.6 | I13: E01 | K13: 13 | L13: Backend | M13: Offen
A14: ST-013 | B14: E02 | C14: Konfliktregeln je Entität | D14: Als Entwickler will ich Konfliktstrategien pro Entität umsetzen, damit Konflikte fast nie beim Nutzer landen. | E14: Setup unveränderlich; Ride nach Finalisierung unveränderlich; Bike feldweise Last-Write-Wins; Konfliktrate messbar unter 0,1 %. | F14: P0 | G14: MVP v1.0 | H14: 5.6 / NFR-14 | I14: E02 | K14: 8 | L14: Backend | M14: Offen
A15: ST-014 | B15: E02 | C15: Granulare Einwilligungen | D15: Als Nutzer will ich jede Datennutzung einzeln erlauben und widerrufen können. | E15: Fünf getrennte Zwecke; Widerruf ohne Nachteil für die Kernfunktion; jede Einwilligung mit Zeitpunkt und Richtlinienversion protokolliert. | F15: P0 | G15: MVP v1.0 | H15: F-ACC-006 / DM-18 | K15: 8 | L15: Mobile | M15: Offen
A16: ST-015 | B16: E02 | C16: Privatsphärenzonen | D16: Als Nutzer will ich Tracks rund um meine Adresse kappen lassen. | E16: Radius einstellbar; Kappung wirkt auf Anzeige, Export und Heatmap-Beitrag; im Onboarding aktiv angeboten. | F16: P0 | G16: MVP v1.0 | H16: F-ACC-005 | K16: 5 | L16: Mobile | M16: Offen
A17: ST-016 | B17: E02 | C17: Datenexport | D17: Als Nutzer will ich alle meine Daten exportieren können. | E17: GPX je Ride und JSON-Vollexport inklusive Garage und Setups; Auslieferung innerhalb 24 h. | F17: P0 | G17: MVP v1.0 | H17: F-ACC-003 | K17: 5 | L17: Backend | M17: Offen
A18: ST-017 | B18: E02 | C18: Kontolöschung | D18: Als Nutzer will ich mein Konto in der App löschen können. | E18: Löschung in der App auslösbar; Bestätigung per E-Mail; vollständige Löschung inklusive Objektspeicher und Backups innerhalb 30 bzw. 90 Tagen nachweisbar. | F18: P0 | G18: MVP v1.0 | H18: F-ACC-004 | K18: 8 | L18: Backend | M18: Offen
A19: ST-018 | B19: E02 | C19: Verschlüsselung lokaler Daten | D19: Als Nutzer will ich, dass meine Daten auf dem Gerät verschlüsselt liegen. | E19: Lokale Datenbank über Keychain bzw. Keystore verschlüsselt; Schlüssel nicht im Backup im Klartext. | F19: P0 | G19: MVP v1.0 | H19: 7.7 | K19: 5 | L19: Mobile | M19: Offen
A20: ST-019 | B20: E03 | C20: Bike per Katalog anlegen | D20: Als Nutzer will ich mein Bike über Hersteller, Modell und Jahr anlegen, damit die Komponentenliste vorbefüllt wird. | E20: Erstes fahrbereites Bike im Median unter 90 s (n>=8, unmoderiert); Komponenten aus der Ausstattungsliste vorbefüllt. | F20: P0 | G20: MVP v1.0 | H20: F-GAR-001 | I20: E16 | J20: G-4 | K20: 8 | L20: Mobile | M20: Offen
A21: ST-020 | B21: E03 | C21: Bike ohne Katalogtreffer anlegen | D21: Als Nutzer mit seltenem Bike will ich Kategorie, Federweg und Laufradgröße angeben und später ergänzen. | E21: Bike ohne Komponenten nutzbar; Funktionen mit Komponentenbedarf zeigen konkreten Hinweis mit Direktlink statt Fehlermeldung. | F21: P0 | G21: MVP v1.0 | H21: F-GAR-001 | K21: 5 | L21: Mobile | M21: Offen
A22: ST-021 | B22: E03 | C22: Aktives Bike | D22: Als Nutzer mit mehreren Bikes will ich eines als aktiv markieren, damit die App weiß, worauf sich alles bezieht. | E22: Genau ein aktives Bike je Nutzer (Datenbank erzwingt es); Bike-Chip auf jedem Top-Level-Screen; Wechsel aktualisiert Discover und Shop sofort. | F22: P0 | G22: MVP v1.0 | H22: F-GAR-001 / 3.1 | I22: E03 | K22: 5 | L22: Mobile | M22: Offen
A23: ST-022 | B23: E03 | C23: Komponentenslots pflegen | D23: Als Nutzer will ich jeden Komponentenslot befüllen, damit Kompatibilität und Setup funktionieren. | E23: 60 Slots je Bike-Typ; Katalogbezug oder Freitext mit Warnhinweis; leerer Slot erscheint als Aufgabe, nicht als Fehler. | F23: P0 | G23: MVP v1.0 | H23: F-GAR-002 | I23: E16 | K23: 8 | L23: Mobile | M23: Offen
A24: ST-023 | B24: E03 | C24: Komponentenhistorie und Laufleistung | D24: Als Nutzer will ich sehen, wie lange ein Teil verbaut ist und wie viel es geleistet hat. | E24: installed_at/removed_at je Komponente; km, Höhenmeter und Stunden aus den Rides des Einbauzeitraums aggregiert; bei Bremsen zusätzlich Abfahrts-Höhenmeter. | F24: P0 | G24: MVP v1.0 | H24: F-GAR-002 / DM-05 | I24: E09 | K24: 8 | L24: Backend | M24: Offen
A25: ST-024 | B25: E03 | C25: Komponente zwischen Bikes verschieben | D25: Als Nutzer mit zwei Bikes will ich einen Laufradsatz umsetzen, ohne die Laufleistung zu verlieren. | E25: Verschiebung überträgt die Laufleistung; Historie beider Bikes bleibt korrekt. | F25: P0 | G25: MVP v1.0 | H25: F-GAR-002 | I25: E03 | K25: 5 | L25: Mobile | M25: Offen
A26: ST-025 | B26: E03 | C26: Fortschrittsanzeige der Bike-Erfassung | D26: Als Nutzer will ich sehen, wie vollständig mein Bike erfasst ist und was der nächste sinnvolle Schritt ist. | E26: Prozentanzeige; genau eine konkrete nächste Aufgabe; jeder ausgefüllte Slot schaltet sichtbaren Nutzen frei. | F26: P0 | G26: MVP v1.0 | H26: R-16 | I26: E03 | K26: 5 | L26: Design | M26: Offen
A27: ST-026 | B27: E03 | C27: Bike-Foto | D27: Als Nutzer will ich ein Foto hinterlegen, damit ich meine Bikes in der Liste erkenne. | E27: Foto aufnehmen oder auswählen; Zuschnitt; lokal gespeichert, Upload nur bei Konto. | F27: P1 | G27: MVP v1.0 | H27: F-GAR-004 | K27: 3 | L27: Mobile | M27: Offen
A28: ST-027 | B28: E03 | C28: Schematische Bike-Darstellung mit Hotspots | D28: Als Nutzer will ich mein Bike als Schema mit Statusfarben je Baugruppe sehen. | E28: 8 Silhouetten; Hotspots je Slot; drei Zustände gepflegt/fällig/Daten fehlen; Tap öffnet die Komponente. | F28: P1 | G28: v1.1–v1.3 | H28: F-GAR-004 | I28: E03 | K28: 8 | L28: Design | M28: Offen
A29: ST-028 | B29: E04 | C29: Regel-Engine mit vier Urteilen | D29: Als Nutzer will ich wissen, ob ein Teil passt, und im Zweifel ein ehrliches „Daten unzureichend“. | E29: Vier Urteile umgesetzt; fehlendes Pflichtattribut führt zwingend zu INSUFFICIENT_DATA; kein Prädikat wird bei fehlenden Werten ausgewertet. | F29: P0 | G29: MVP v1.0 | H29: F-GAR-003 | I29: E01 | K29: 13 | L29: Backend | M29: Offen
A30: ST-029 | B30: E04 | C30: Regel-Syntax und Auswerter | D30: Als Regelautor will ich Regeln deklarativ und ohne Programmierung schreiben. | E30: YAML-Schema; statische Prüfung; Auswerter ohne Turing-Vollständigkeit; Regelsatz versioniert. | F30: P0 | G30: MVP v1.0 | H30: 6.6 | I30: E04 | K30: 8 | L30: Backend | M30: Offen
A31: ST-030 | B31: E04 | C31: Begründungskette anzeigen | D31: Als Nutzer will ich sehen, warum ein Urteil zustande kam. | E31: Regel-ID, verglichene Werte, Quelle je Wert mit Datum; von jedem Urteil per Tap erreichbar. | F31: P0 | G31: MVP v1.0 | H31: F-GAR-003.2 | I31: E04 | K31: 8 | L31: Mobile | M31: Offen
A32: ST-031 | B32: E04 | C32: Regel-Regressionsset | D32: Als Qualitätsverantwortlicher will ich, dass keine Regel ohne Tests in Produktion geht. | E32: Mindestens drei Testfälle je Regel (pass/fail/insufficient); Build lehnt Regeln ohne Tests ab. | F32: P0 | G32: MVP v1.0 | H32: 6.6 | I32: E04 | K32: 5 | L32: QA | M32: Offen
A33: ST-032 | B33: E04 | C33: Zweitprüfung sicherheitskritischer Regeln | D33: Als Produktverantwortlicher will ich, dass sicherheitskritische Regeln vier Augen gesehen haben. | E33: reviewed_by und reviewed_at sind Pflichtfelder; Auslieferung ohne Zweitprüfung technisch blockiert. | F33: P0 | G33: MVP v1.0 | H33: DM-14 | I33: E04 | K33: 3 | L33: Backend | M33: Offen
A34: ST-033 | B34: E04 | C34: Prüfprotokoll speichern | D34: Als Betreiber will ich jede Prüfung mit Regelsatzversion protokollieren, damit vergangene Urteile rekonstruierbar bleiben. | E34: compatibility_check mit Belegen und Regelsatzversion; Aufbewahrung 24 Monate. | F34: P0 | G34: MVP v1.0 | H34: DM-15 | I34: E04 | K34: 3 | L34: Backend | M34: Offen
A35: ST-034 | B35: E04 | C35: Sicherheitshinweise und Drehmomente | D35: Als Nutzer will ich bei sicherheitsrelevanten Teilen den Werkstatthinweis und die Herstellerdrehmomente sehen. | E35: Hinweis bei 9 definierten Kategorien; Drehmomente ausschließlich aus Herstellerdokumenten, nie geschätzt. | F35: P0 | G35: MVP v1.0 | H35: F-GAR-003.3 | I35: E16 | K35: 5 | L35: Mobile | M35: Offen
A36: ST-035 | B36: E04 | C36: Fehlendes Attribut ergänzen | D36: Als Nutzer will ich ein fehlendes Merkmal selbst nachtragen und sofort ein neues Urteil bekommen. | E36: Aufforderung nennt das konkrete Attribut; Neuprüfung unmittelbar; Nutzereingabe als Quelle gekennzeichnet. | F36: P0 | G36: MVP v1.0 | H36: F-GAR-003.1 | I36: E04 | K36: 5 | L36: Mobile | M36: Offen
A37: ST-036 | B37: E05 | C37: Setup als unveränderliche Version | D37: Als Nutzer will ich, dass jede Setup-Änderung eine neue Version erzeugt, damit meine Historie belastbar bleibt. | E37: Neue Version mit Verweis auf die Vorgängerversion; alte Versionen nie überschrieben; genau ein aktuelles Setup je Bike. | F37: P0 | G37: MVP v1.0 | H37: F-SET-001 / DM-06 | I37: E03 | K37: 8 | L37: Backend | M37: Offen
A38: ST-037 | B38: E05 | C38: Generischer Setup-Editor | D38: Als Nutzer will ich nur die Regler sehen, die meine Komponente tatsächlich hat. | E38: Regler werden aus dem Katalogeintrag abgeleitet; Klick-Stepper mit Haptik; Herstellergrenzen als harter Anschlag mit Erklärung. | F38: P0 | G38: MVP v1.0 | H38: F-SET-001 / DM-03 | I38: E16 | K38: 13 | L38: Mobile | M38: Offen
A39: ST-038 | B39: E05 | C39: Einheiten und Klick-Referenz | D39: Als Nutzer will ich psi oder bar sehen und wissen, ob von offen oder von geschlossen gezählt wird. | E39: Speicherung in SI-Einheiten; Anzeige nach Nutzerpräferenz; Klicks intern immer von geschlossen, Anzeige folgt der Herstellerkonvention und benennt sie. | F39: P0 | G39: MVP v1.0 | H39: 6.4 | I39: E05 | K39: 5 | L39: Mobile | M39: Offen
... A62: ST-061 | B62: E08 | C62: Flow-Score mit offenen Teilwerten | D62: Als Nutzer will ich verstehen, woraus mein Flow-Score entsteht. | E62: Vier Teilwerte einzeln sichtbar; Terrainnormierung; kein nutzerübergreifender Vergleich, keine öffentlichen Bestenlisten. | F62: P0 | G62: MVP v1.0 | H62: F-SEN-004 / R-09 | I62: E07 | K62: 8 | L62: ML | M62: Offen
...

Sheet Epics
A1: Auswertung je Epic
A2: Alle Werte sind Formeln auf das Blatt Backlog. Nur die gelbe Zelle ist eine Eingabe.
A3: Velocity (SP je Sprint) | B3: 90 | C3: Rückgerechnet aus Kapitel 9.3 (fünf Monate MVP-Bau = zehn Sprints). Konsistenzannahme, keine gemessene Velocity — im ersten Planning ersetzen.
A5: Epic | B5: Bezeichnung | C5: Stories | D5: SP gesamt | E5: SP MVP v1.0 | F5: SP v1.1–v1.3 | G5: SP Phase 2+ | H5: Offen | I5: Fertig
A6: E01 | B6: Fundament & Plattform | C6: =COUNTIFS(Backlog!$B$2:$B$136,$A6) -> 9 | D6: =SUMIFS(Backlog!$K$2:$K$136,Backlog!$B$2:$B$136,$A6) -> 50 | E6: =SUMIFS(Backlog!$K$2:$K$136,Backlog!$B$2:$B$136,$A6,Backlog!$G$2:$G$136,"MVP v1.0") -> 50 | F6: =SUMIFS(Backlog!$K$2:$K$136,Backlog!$B$2:$B$136,$A6,Backlog!$G$2:$G$136,"v1.1–v1.3") -> 0 | G6: =$D6-$E6-$F6 -> 0 | H6: =COUNTIFS(Backlog!$B$2:$B$136,$A6,Backlog!$M$2:$M$136,"Offen") -> 9 | I6: =COUNTIFS(Backlog!$B$2:$B$136,$A6,Backlog!$M$2:$M$136,"Fertig") -> 0
A7: E02 | B7: Konto, Datenschutz & Sync | C7: =COUNTIFS(Backlog!$B$2:$B$136,$A7) -> 9 | D7: =SUMIFS(Backlog!$K$2:$K$136,Backlog!$B$2:$B$136,$A7) -> 65 | E7: =SUMIFS(Backlog!$K$2:$K$136,Backlog!$B$2:$B$136,$A7,Backlog!$G$2:$G$136,"MVP v1.0") -> 65 | F7: =SUMIFS(Backlog!$K$2:$K$136,Backlog!$B$2:$B$136,$A7,Backlog!$G$2:$G$136,"v1.1–v1.3") -> 0 | G7: =$D7-$E7-$F7 -> 0 | H7: =COUNTIFS(Backlog!$B$2:$B$136,$A7,Backlog!$M$2:$M$136,"Offen") -> 9 | I7: =COUNTIFS(Backlog!$B$2:$B$136,$A7,Backlog!$M$2:$M$136,"Fertig") -> 0
A8: E03 | B8: Garage & Komponenten | C8: =COUNTIFS(Backlog!$B$2:$B$136,$A8) -> 9 | D8: =SUMIFS(Backlog!$K$2:$K$136,Backlog!$B$2:$B$136,$A8) -> 55 | E8: =SUMIFS(Backlog!$K$2:$K$136,Backlog!$B$2:$B$136,$A8,Backlog!$G$2:$G$136,"MVP v1.0") -> 47 | F8: =SUMIFS(Backlog!$K$2:$K$136,Backlog!$B$2:$B$136,$A8,Backlog!$G$2:$G$136,"v1.1–v1.3") -> 8 | G8: =$D8-$E8-$F8 -> 0 | H8: =COUNTIFS(Backlog!$B$2:$B$136,$A8,Backlog!$M$2:$M$136,"Offen") -> 9 | I8: =COUNTIFS(Backlog!$B$2:$B$136,$A8,Backlog!$M$2:$M$136,"Fertig") -> 0
A9: E04 | B9: Kompatibilitäts-Engine | C9: =COUNTIFS(Backlog!$B$2:$B$136,$A9) -> 8 | D9: =SUMIFS(Backlog!$K$2:$K$136,Backlog!$B$2:$B$136,$A9) -> 50 | E9: =SUMIFS(Backlog!$K$2:$K$136,Backlog!$B$2:$B$136,$A9,Backlog!$G$2:$G$136,"MVP v1.0") -> 50 | F9: =SUMIFS(Backlog!$K$2:$K$136,Backlog!$B$2:$B$136,$A9,Backlog!$G$2:$G$136,"v1.1–v1.3") -> 0 | G9: =$D9-$E9-$F9 -> 0 | H9: =COUNTIFS(Backlog!$B$2:$B$136,$A9,Backlog!$M$2:$M$136,"Offen") -> 8 | I9: =COUNTIFS(Backlog!$B$2:$B$136,$A9,Backlog!$M$2:$M$136,"Fertig") -> 0
A10: E05 | B10: Setup & Bracketing | C10: =COUNTIFS(Backlog!$B$2:$B$136,$A10) -> 12 | D10: =SUMIFS(Backlog!$K$2:$K$136,Backlog!$B$2:$B$136,$A10) -> 91 | E10: =SUMIFS(Backlog!$K$2:$K$136,Backlog!$B$2:$B$136,$A10,Backlog!$G$2:$G$136,"MVP v1.0") -> 86 | F10: =SUMIFS(Backlog!$K$2:$K$136,Backlog!$B$2:$B$136,$A10,Backlog!$G$2:$G$136,"v1.1–v1.3") -> 5 | G10: =$D10-$E10-$F10 -> 0 | H10: =COUNTIFS(Backlog!$B$2:$B$136,$A10,Backlog!$M$2:$M$136,"Offen") -> 12 | I10: =COUNTIFS(Backlog!$B$2:$B$136,$A10,Backlog!$M$2:$M$136,"Fertig") -> 0
A11: E06 | B11: Wartung | C11: =COUNTIFS(Backlog!$B$2:$B$136,$A11) -> 3 | D11: =SUMIFS(Backlog!$K$2:$K$136,Backlog!$B$2:$B$136,$A11) -> 21 | E11: =SUMIFS(Backlog!$K$2:$K$136,Backlog!$B$2:$B$136,$A11,Backlog!$G$2:$G$136,"MVP v1.0") -> 13 | F11: =SUMIFS(Backlog!$K$2:$K$136,Backlog!$B$2:$B$136,$A11,Backlog!$G$2:$G$136,"v1.1–v1.3") -> 8 | G11: =$D11-$E11-$F11 -> 0 | H11: =COUNTIFS(Backlog!$B$2:$B$136,$A11,Backlog!$M$2:$M$136,"Offen") -> 3 | I11: =COUNTIFS(Backlog!$B$2:$B$136,$A11,Backlog!$M$2:$M$136,"Fertig") -> 0
A12: E07 | B12: Sensorik & Kalibrierung | C12: =COUNTIFS(Backlog!$B$2:$B$136,$A12) -> 8 | D12: =SUMIFS(Backlog!$K$2:$K$136,Backlog!$B$2:$B$136,$A12) -> 66 | E12: =SUMIFS(Backlog!$K$2:$K$136,Backlog!$B$2:$B$136,$A12,Backlog!$G$2:$G$136,"MVP v1.0") -> 66 | F12: =SUMIFS(Backlog!$K$2:$K$136,Backlog!$B$2:$B$136,$A12,Backlog!$G$2:$G$136,"v1.1–v1.3") -> 0 | G12: =$D12-$E12-$F12 -> 0 | H12: =COUNTIFS(Backlog!$B$2:$B$136,$A12,Backlog!$M$2:$M$136,"Offen") -> 8 | I12: =COUNTIFS(Backlog!$B$2:$B$136,$A12,Backlog!$M$2:$M$136,"Fertig") -> 0
A13: E08 | B13: Fahrwerksanalyse (Gate G-2) | C13: =COUNTIFS(Backlog!$B$2:$B$136,$A13) -> 9 | D13: =SUMIFS(Backlog!$K$2:$K$136,Backlog!$B$2:$B$136,$A13) -> 82 | E13: =SUMIFS(Backlog!$K$2:$K$136,Backlog!$B$2:$B$136,$A13,Backlog!$G$2:$G$136,"MVP v1.0") -> 82 | F13: =SUMIFS(Backlog!$K$2:$K$136,Backlog!$B$2:$B$136,$A13,Backlog!$G$2:$G$136,"v1.1–v1.3") -> 0 | G13: =$D13-$E13-$F13 -> 0 | H13: =COUNTIFS(Backlog!$B$2:$B$136,$A13,Backlog!$M$2:$M$136,"Offen") -> 9 | I13: =COUNTIFS(Backlog!$B$2:$B$136,$A13,Backlog!$M$2:$M$136,"Fertig") -> 0
A14: E09 | B14: Ride-Erfassung & Ride-UI | C14: =COUNTIFS(Backlog!$B$2:$B$136,$A14) -> 8 | D14: =SUMIFS(Backlog!$K$2:$K$136,Backlog!$B$2:$B$136,$A14) -> 55 | E14: =SUMIFS(Backlog!$K$2:$K$136,Backlog!$B$2:$B$136,$A14,Backlog!$G$2:$G$136,"MVP v1.0") -> 55 | F14: =SUMIFS(Backlog!$K$2:$K$136,Backlog!$B$2:$B$136,$A14,Backlog!$G$2:$G$136,"v1.1–v1.3") -> 0 | G14: =$D14-$E14-$F14 -> 0 | H14: =COUNTIFS(Backlog!$B$2:$B$136,$A14,Backlog!$M$2:$M$136,"Offen") -> 8 | I14: =COUNTIFS(Backlog!$B$2:$B$136,$A14,Backlog!$M$2:$M$136,"Fertig") -> 0
A15: E10 | B15: Navigation & Offline | C15: =COUNTIFS(Backlog!$B$2:$B$136,$A15) -> 12 | D15: =SUMIFS(Backlog!$K$2:$K$136,Backlog!$B$2:$B$136,$A15) -> 118 | E15: =SUMIFS(Backlog!$K$2:$K$136,Backlog!$B$2:$B$136,$A15,Backlog!$G$2:$G$136,"MVP v1.0") -> 97 | F15: =SUMIFS(Backlog!$K$2:$K$136,Backlog!$B$2:$B$136,$A15,Backlog!$G$2:$G$136,"v1.1–v1.3") -> 0 | G15: =$D15-$E15-$F15 -> 21 | H15: =COUNTIFS(Backlog!$B$2:$B$136,$A15,Backlog!$M$2:$M$136,"Offen") -> 12 | I15: =COUNTIFS(Backlog!$B$2:$B$136,$A15,Backlog!$M$2:$M$136,"Fertig") -> 0
A16: E11 | B16: Post-Ride & Empfehlungen | C16: =COUNTIFS(Backlog!$B$2:$B$136,$A16) -> 6 | D16: =SUMIFS(Backlog!$K$2:$K$136,Backlog!$B$2:$B$136,$A16) -> 44 | E16: =SUMIFS(Backlog!$K$2:$K$136,Backlog!$B$2:$B$136,$A16,Backlog!$G$2:$G$136,"MVP v1.0") -> 44 | F16: =SUMIFS(Backlog!$K$2:$K$136,Backlog!$B$2:$B$136,$A16,Backlog!$G$2:$G$136,"v1.1–v1.3") -> 0 | G16: =$D16-$E16-$F16 -> 0 | H16: =COUNTIFS(Backlog!$B$2:$B$136,$A16,Backlog!$M$2:$M$136,"Offen") -> 6 | I16: =COUNTIFS(Backlog!$B$2:$B$136,$A16,Backlog!$M$2:$M$136,"Fertig") -> 0
A17: E12 | B17: E-Bike-Integration | C17: =COUNTIFS(Backlog!$B$2:$B$136,$A17) -> 7 | D17: =SUMIFS(Backlog!$K$2:$K$136,Backlog!$B$2:$B$136,$A17) -> 58 | E17: =SUMIFS(Backlog!$K$2:$K$136,Backlog!$B$2:$B$136,$A17,Backlog!$G$2:$G$136,"MVP v1.0") -> 45 | F17: =SUMIFS(Backlog!$K$2:$K$136,Backlog!$B$2:$B$136,$A17,Backlog!$G$2:$G$136,"v1.1–v1.3") -> 8 | G17: =$D17-$E17-$F17 -> 5 | H17: =COUNTIFS(Backlog!$B$2:$B$136,$A17,Backlog!$M$2:$M$136,"Offen") -> 7 | I17: =COUNTIFS(Backlog!$B$2:$B$136,$A17,Backlog!$M$2:$M$136,"Fertig") -> 0
... A23: E18 | B23: Qualität, Release & Compliance | C23: =COUNTIFS(Backlog!$B$2:$B$136,$A23) -> 9 | D23: =SUMIFS(Backlog!$K$2:$K$136,Backlog!$B$2:$B$136,$A23) -> 55 | E23: =SUMIFS(Backlog!$K$2:$K$136,Backlog!$B$2:$B$136,$A23,Backlog!$G$2:$G$136,"MVP v1.0") -> 55 | F23: =SUMIFS(Backlog!$K$2:$K$136,Backlog!$B$2:$B$136,$A23,Backlog!$G$2:$G$136,"v1.1–v1.3") -> 0 | G23: =$D23-$E23-$F23 -> 0 | H23: =COUNTIFS(Backlog!$B$2:$B$136,$A23,Backlog!$M$2:$M$136,"Offen") -> 9 | I23: =COUNTIFS(Backlog!$B$2:$B$136,$A23,Backlog!$M$2:$M$136,"Fertig") -> 0
B24: Summe | C24: =SUM(C6:C23) -> 135 | D24: =SUM(D6:D23) -> 1037 | E24: =SUM(E6:E23) -> 888 | F24: =SUM(F6:F23) -> 97 | G24: =SUM(G6:G23) -> 52 | H24: =SUM(H6:H23) -> 135 | I24: =SUM(I6:I23) -> 0
A26: Hochrechnung
A27: Stories gesamt | B27: =C24 -> 135
A28: Story Points gesamt | B28: =D24 -> 1037
A29: Story Points MVP v1.0 | B29: =E24 -> 888
A30: Sprints für den MVP (bei Velocity oben) | B30: =IFERROR(ROUNDUP(E24/$B$3,0),"—") -> 10
A31: entspricht Monaten (2-Wochen-Sprints) | B31: =IFERROR(ROUND(ROUNDUP(E24/$B$3,0)*0.5,1),"—") -> 5
A32: Plan laut Spezifikation Kap. 9.3 | B32: 5
A33: Anteil MVP an allen Punkten | B33: =IFERROR(E24/D24,"—") -> 0.8563163
A34: Punkte, die an Gate G-2 hängen | B34: =SUMIFS(Backlog!$K$2:$K$136,Backlog!$J$2:$J$136,"G-2") -> 55
A35: Punkte, die an Gate G-1 hängen | B35: =SUMIFS(Backlog!$K$2:$K$136,Backlog!$J$2:$J$136,"G-1") -> 13
A36: Punkte im Epic E16 (Katalog, kritischer Pfad) | B36: =SUMIFS(Backlog!$K$2:$K$136,Backlog!$B$2:$B$136,"E16") -> 68
A38: Die Zeile „entspricht Monaten“ muss zur Planzeile darunter passen. Tut sie das nach dem ersten Planning nicht, ist entweder die Schätzung oder der Termin falsch — nicht beides ignorieren. Die Hochrechnung enthält keine Puffer für Feldstudie, Beta, Store-Prüfung und Rechtsberatung — diese laufen parallel und sind in Kapitel 9.3 der Spezifikation terminiert.

Sheet Gates
A1: Entscheidungspunkte
A2: Stories mit Gate-Eintrag im Backlog starten erst nach positivem Ergebnis.
A4: Gate | B4: Gegenstand | C4: Bedingung | D4: Konsequenz bei Nichterfüllung | E4: Verantwortung | F4: Fällig | G4: Gebundene SP
A5: G-0 | B5: Team-Aufstellung | C5: Mobile-Technologie gegen reale Teamprofile bestätigt | D5: Architekturentscheidung aus Kapitel 5.1 neu bewerten | E5: Eng-Lead | F5: vor Sprint 1 | G5: =SUMIFS(Backlog!$K$2:$K$136,Backlog!$J$2:$J$136,$A5) -> 3
A6: G-1 | B6: Bosch Live Data Interface | C6: Zugang, Nutzungsbedingungen und Markenrichtlinien geklärt und erfüllbar | D6: E-Bike-Telemetrie entfällt, manuelle Stufe bleibt; Marketingaussagen anpassen | E6: PM | F6: vor Sprint 1 | G6: =SUMIFS(Backlog!$K$2:$K$136,Backlog!$J$2:$J$136,$A6) -> 13
A7: G-2 | B7: Fahrwerksvalidierung | C7: Sieben Messkriterien im Feld erfüllt (Kap. 7.5) | D7: Fahrwerksfunktionen gehen nicht live; Produktversprechen und Preismodell überarbeiten | E7: ML-Lead | F7: Monat 7 | G7: =SUMIFS(Backlog!$K$2:$K$136,Backlog!$J$2:$J$136,$A7) -> 55
A8: G-3 | B8: Shimano-Lizenz | C8: Vertrag unterzeichnet | D8: Direktanbindung ersatzlos gestrichen; Planung läuft ohnehin ohne | E8: PM | F8: Monat 6 | G8: =SUMIFS(Backlog!$K$2:$K$136,Backlog!$J$2:$J$136,$A8) -> 5
A9: G-4 | B9: Katalogabdeckung | C9: Mind. 3.000 Komponentenmodelle in den zehn wichtigsten Kategorien | D9: Kompatibilitätsprüfung startet eingeschränkt und offen kommuniziert | E9: Data-Lead | F9: Monat 7 | G9: =SUMIFS(Backlog!$K$2:$K$136,Backlog!$J$2:$J$136,$A9) -> 21
A10: G-5 | B10: Wegerecht | C10: Rechtslage je Zielmarkt geprüft | D10: Markteinführung nur in geprüften Ländern | E10: Legal | F10: Monat 8 | G10: =SUMIFS(Backlog!$K$2:$K$136,Backlog!$J$2:$J$136,$A10) -> 8

Sheet Risiken
A1: Risikoregister
A2: Aus Kapitel 10 der Spezifikation. Bewertung als Wahrscheinlichkeit / Auswirkung.
A4: Nr. | B4: Risiko | C4: W | D4: A | E4: Gegenmaßnahme | F4: Verantwortung
A5: R-16 | B5: Nutzer pflegen ihre Garage nicht — das Fundament bleibt leer | C5: mittel | D5: sehr hoch | E5: Vorbefüllung aus OEM-Ausstattungslisten als Standardweg; jeder ausgefüllte Slot schaltet sofort Nutzen frei; Fortschrittsanzeige mit konkretem nächstem Schritt | F5: Design + PM
A6: R-04 | B6: Katalogdaten unvollständig — zu viele „Daten unzureichend“-Urteile | C6: hoch | D6: hoch | E6: Eigene Rolle ab Monat 1; Start mit den zehn kaufhäufigsten Kategorien; Nutzerbeiträge mit Prüfung; Abdeckungsquote als Wochenkennzahl | F6: Data-Lead
A7: R-07 | B7: Haftung für Setup-Empfehlungen im Schadensfall | C7: niedrig | D7: sehr hoch | E7: Nie außerhalb der Herstellergrenzen; keine Empfehlungen zu sicherheitsrelevanten Eingriffen; jede Empfehlung protokolliert; anwaltlich geprüfte Hinweistexte; Produkthaftpflicht | F7: Legal + PM
A8: R-03 | B8: Fahrwerksvalidierung G-2 scheitert | C8: mittel | D8: hoch | E8: Studie ab Monat 5 statt kurz vor Launch; Produkt trägt auch ohne; Preismodell mit Rückfallvariante | F8: ML-Lead
A9: R-11 | B9: Umfang wächst unkontrolliert | C9: hoch | D9: hoch | E9: Nordstern-Metrik als Entscheidungsgrundlage; Prioritätsstufe je Feature-ID; kein Feature ohne zugeordnete Kennzahl | F9: PM
A10: R-13 | B10: Datenschutzverstoß bei Standort- und Gesundheitsdaten | C10: niedrig | D10: sehr hoch | E10: DSFA vor Launch; granulare Einwilligungen; Privatsphärenzonen als Voreinstellung; Datensparsamkeit gegenüber dem Sprachmodell-Anbieter | F10: DSB
A11: R-14 | B11: GNSS-Ungenauigkeit im Wald verfälscht das Segment-Matching | C11: hoch | D11: mittel | E11: Abgleich über Geometrie, Barometerprofil und Sensorsignatur; match_quality je Segment; bei geringer Übereinstimmung keine Auswertung | F11: ML-Lead
A12: R-05 | B12: Akkuverbrauch inakzeptabel | C12: mittel | D12: hoch | E12: NFR ab Sprint 1 in CI messen; adaptive Abtastrate als Rückfallebene; Energiesparmodus im Ride-Screen | F12: Mobile-Lead
A13: R-01 | B13: Bosch-Zugang an nicht erfüllbare Bedingungen geknüpft | C13: mittel | D13: hoch | E13: Gate G-1 vor Sprint 1; manuelle Stufe und Standard-Bluetooth tragen den Nutzen; Marketing erst nach Klärung | F13: PM
A14: R-02 | B14: Shimano-Lizenz kommt nicht zustande | C14: hoch | D14: mittel | E14: Von Beginn an nicht eingeplant; Kommunikation ab Tag 1 ehrlich | F14: PM
A15: R-12 | B15: Sprachmodell erzeugt plausible, aber falsche Werte | C15: mittel | D15: hoch | E15: Numeric-Guard als harte Sperre; deterministischer Ersatztext; Verwerfungsrate als überwachte Kennzahl | F15: ML-Lead
... A20: R-06 | B20: Heatmaps ohne Nutzerbasis wertlos | C20: hoch | D20: niedrig | E20: Erst Phase 2; kein Zukauf mit ungeklärter Lizenz | F20: PM
